<?xml version="1.0" ?>
<!--
  Chambers Testbed - Basic Vehicle Model for Gazebo Fortress (Ignition)

  A simplified vehicle with:
  - Box chassis (4.5m x 1.8m x 1.5m)
  - 4 wheels with revolute joints
  - Sensor plugins: front camera, roof LiDAR, IMU, NavSat (GPS)
  - Differential drive plugin for basic locomotion

  Usage with Gazebo (gz sim):
    gz sim -r vehicle_model.sdf

  Usage with ROS 2 launch:
    See ecu_sim_launch.py
-->
<sdf version="1.9">
  <world name="chambers_vehicle_world">

    <!-- Physics -->
    <physics name="default_physics" type="ode">
      <max_step_size>0.001</max_step_size>
      <real_time_factor>1.0</real_time_factor>
      <real_time_update_rate>1000</real_time_update_rate>
    </physics>

    <!-- Plugins -->
    <plugin filename="gz-sim-physics-system" name="gz::sim::systems::Physics"/>
    <plugin filename="gz-sim-user-commands-system" name="gz::sim::systems::UserCommands"/>
    <plugin filename="gz-sim-scene-broadcaster-system" name="gz::sim::systems::SceneBroadcaster"/>
    <plugin filename="gz-sim-sensors-system" name="gz::sim::systems::Sensors">
      <render_engine>ogre2</render_engine>
    </plugin>
    <plugin filename="gz-sim-imu-system" name="gz::sim::systems::Imu"/>
    <plugin filename="gz-sim-navsat-system" name="gz::sim::systems::NavSat"/>
    <plugin filename="gz-sim-contact-system" name="gz::sim::systems::Contact"/>

    <!-- Scene -->
    <scene>
      <ambient>0.8 0.8 0.8 1.0</ambient>
      <background>0.3 0.5 0.8 1.0</background>
      <shadows>true</shadows>
    </scene>

    <!-- Sun -->
    <light type="directional" name="sun">
      <cast_shadows>true</cast_shadows>
      <pose>0 0 10 0 0 0</pose>
      <diffuse>1.0 1.0 1.0 1</diffuse>
      <specular>0.5 0.5 0.5 1</specular>
      <direction>-0.5 0.1 -0.9</direction>
    </light>

    <!-- Ground plane -->
    <model name="ground_plane">
      <static>true</static>
      <link name="link">
        <collision name="collision">
          <geometry>
            <plane>
              <normal>0 0 1</normal>
              <size>500 500</size>
            </plane>
          </geometry>
          <surface>
            <friction>
              <ode>
                <mu>100</mu>
                <mu2>50</mu2>
              </ode>
            </friction>
          </surface>
        </collision>
        <visual name="visual">
          <geometry>
            <plane>
              <normal>0 0 1</normal>
              <size>500 500</size>
            </plane>
          </geometry>
          <material>
            <ambient>0.4 0.4 0.4 1</ambient>
            <diffuse>0.5 0.5 0.5 1</diffuse>
          </material>
        </visual>
      </link>
    </model>

    <!-- ================================================================ -->
    <!-- VEHICLE MODEL                                                     -->
    <!-- ================================================================ -->
    <model name="chambers_vehicle">
      <pose>0 0 0.4 0 0 0</pose>

      <!-- ============================================================ -->
      <!-- CHASSIS                                                       -->
      <!-- ============================================================ -->
      <link name="chassis">
        <pose>0 0 0.35 0 0 0</pose>
        <inertial>
          <mass>1500.0</mass>
          <inertia>
            <ixx>337.5</ixx>  <!-- 1/12 * m * (h^2 + d^2) -->
            <iyy>843.75</iyy> <!-- 1/12 * m * (w^2 + l^2) -->
            <iyz>0</iyz>
            <izz>618.75</izz> <!-- 1/12 * m * (w^2 + h^2) -->
            <ixy>0</ixy>
            <ixz>0</ixz>
          </inertia>
        </inertial>

        <collision name="chassis_collision">
          <geometry>
            <box>
              <size>4.5 1.8 1.5</size>
            </box>
          </geometry>
        </collision>

        <visual name="chassis_visual">
          <geometry>
            <box>
              <size>4.5 1.8 1.5</size>
            </box>
          </geometry>
          <material>
            <ambient>0.15 0.25 0.45 1</ambient>
            <diffuse>0.2 0.35 0.6 1</diffuse>
            <specular>0.8 0.8 0.8 1</specular>
          </material>
        </visual>

        <!-- ========================================================== -->
        <!-- SENSORS                                                     -->
        <!-- ========================================================== -->

        <!-- Front RGB Camera -->
        <sensor name="front_camera" type="camera">
          <pose>2.1 0 0.6 0 0 0</pose>
          <always_on>true</always_on>
          <update_rate>10</update_rate>
          <visualize>true</visualize>
          <topic>chambers/camera/front/image_raw</topic>
          <camera>
            <horizontal_fov>1.5708</horizontal_fov> <!-- 90 degrees -->
            <image>
              <width>1280</width>
              <height>720</height>
              <format>R8G8B8</format>
            </image>
            <clip>
              <near>0.1</near>
              <far>300.0</far>
            </clip>
            <noise>
              <type>gaussian</type>
              <mean>0.0</mean>
              <stddev>0.007</stddev>
            </noise>
          </camera>
        </sensor>

        <!-- Roof LiDAR -->
        <sensor name="roof_lidar" type="gpu_lidar">
          <pose>0 0 1.3 0 0 0</pose>
          <always_on>true</always_on>
          <update_rate>10</update_rate>
          <visualize>true</visualize>
          <topic>chambers/lidar/roof/points</topic>
          <lidar>
            <scan>
              <horizontal>
                <samples>1800</samples>
                <resolution>1</resolution>
                <min_angle>-3.14159</min_angle>
                <max_angle>3.14159</max_angle>
              </horizontal>
              <vertical>
                <samples>32</samples>
                <resolution>1</resolution>
                <min_angle>-0.5236</min_angle>  <!-- -30 degrees -->
                <max_angle>0.1745</max_angle>   <!-- +10 degrees -->
              </vertical>
            </scan>
            <range>
              <min>0.5</min>
              <max>100.0</max>
              <resolution>0.01</resolution>
            </range>
            <noise>
              <type>gaussian</type>
              <mean>0.0</mean>
              <stddev>0.02</stddev>
            </noise>
          </lidar>
        </sensor>

        <!-- IMU -->
        <sensor name="imu_sensor" type="imu">
          <pose>0 0 0 0 0 0</pose>
          <always_on>true</always_on>
          <update_rate>100</update_rate>
          <topic>chambers/imu/data</topic>
          <imu>
            <angular_velocity>
              <x>
                <noise type="gaussian">
                  <mean>0.0</mean>
                  <stddev>0.01</stddev>
                </noise>
              </x>
              <y>
                <noise type="gaussian">
                  <mean>0.0</mean>
                  <stddev>0.01</stddev>
                </noise>
              </y>
              <z>
                <noise type="gaussian">
                  <mean>0.0</mean>
                  <stddev>0.01</stddev>
                </noise>
              </z>
            </angular_velocity>
            <linear_acceleration>
              <x>
                <noise type="gaussian">
                  <mean>0.0</mean>
                  <stddev>0.1</stddev>
                </noise>
              </x>
              <y>
                <noise type="gaussian">
                  <mean>0.0</mean>
                  <stddev>0.1</stddev>
                </noise>
              </y>
              <z>
                <noise type="gaussian">
                  <mean>0.0</mean>
                  <stddev>0.1</stddev>
                </noise>
              </z>
            </linear_acceleration>
          </imu>
        </sensor>

        <!-- NavSat (GPS) -->
        <sensor name="gps_sensor" type="navsat">
          <pose>0 0 0.8 0 0 0</pose>
          <always_on>true</always_on>
          <update_rate>10</update_rate>
          <topic>chambers/navsat/fix</topic>
          <navsat>
            <position_sensing>
              <horizontal>
                <noise type="gaussian">
                  <mean>0.0</mean>
                  <stddev>1.0</stddev>
                </noise>
              </horizontal>
              <vertical>
                <noise type="gaussian">
                  <mean>0.0</mean>
                  <stddev>2.0</stddev>
                </noise>
              </vertical>
            </position_sensing>
            <velocity_sensing>
              <horizontal>
                <noise type="gaussian">
                  <mean>0.0</mean>
                  <stddev>0.1</stddev>
                </noise>
              </horizontal>
              <vertical>
                <noise type="gaussian">
                  <mean>0.0</mean>
                  <stddev>0.2</stddev>
                </noise>
              </vertical>
            </velocity_sensing>
          </navsat>
        </sensor>

      </link>

      <!-- ============================================================ -->
      <!-- WHEELS                                                        -->
      <!-- ============================================================ -->

      <!-- Front Left Wheel -->
      <link name="front_left_wheel">
        <pose>1.4 1.0 0 -1.5708 0 0</pose>
        <inertial>
          <mass>15.0</mass>
          <inertia>
            <ixx>0.3375</ixx>
            <iyy>0.3375</iyy>
            <izz>0.5625</izz>
            <ixy>0</ixy>
            <ixz>0</ixz>
            <iyz>0</iyz>
          </inertia>
        </inertial>
        <collision name="collision">
          <geometry>
            <cylinder>
              <radius>0.35</radius>
              <length>0.22</length>
            </cylinder>
          </geometry>
          <surface>
            <friction>
              <ode>
                <mu>1.0</mu>
                <mu2>0.8</mu2>
              </ode>
            </friction>
          </surface>
        </collision>
        <visual name="visual">
          <geometry>
            <cylinder>
              <radius>0.35</radius>
              <length>0.22</length>
            </cylinder>
          </geometry>
          <material>
            <ambient>0.1 0.1 0.1 1</ambient>
            <diffuse>0.15 0.15 0.15 1</diffuse>
          </material>
        </visual>
      </link>

      <!-- Front Right Wheel -->
      <link name="front_right_wheel">
        <pose>1.4 -1.0 0 -1.5708 0 0</pose>
        <inertial>
          <mass>15.0</mass>
          <inertia>
            <ixx>0.3375</ixx>
            <iyy>0.3375</iyy>
            <izz>0.5625</izz>
            <ixy>0</ixy>
            <ixz>0</ixz>
            <iyz>0</iyz>
          </inertia>
        </inertial>
        <collision name="collision">
          <geometry>
            <cylinder>
              <radius>0.35</radius>
              <length>0.22</length>
            </cylinder>
          </geometry>
          <surface>
            <friction>
              <ode>
                <mu>1.0</mu>
                <mu2>0.8</mu2>
              </ode>
            </friction>
          </surface>
        </collision>
        <visual name="visual">
          <geometry>
            <cylinder>
              <radius>0.35</radius>
              <length>0.22</length>
            </cylinder>
          </geometry>
          <material>
            <ambient>0.1 0.1 0.1 1</ambient>
            <diffuse>0.15 0.15 0.15 1</diffuse>
          </material>
        </visual>
      </link>

      <!-- Rear Left Wheel -->
      <link name="rear_left_wheel">
        <pose>-1.4 1.0 0 -1.5708 0 0</pose>
        <inertial>
          <mass>15.0</mass>
          <inertia>
            <ixx>0.3375</ixx>
            <iyy>0.3375</iyy>
            <izz>0.5625</izz>
            <ixy>0</ixy>
            <ixz>0</ixz>
            <iyz>0</iyz>
          </inertia>
        </inertial>
        <collision name="collision">
          <geometry>
            <cylinder>
              <radius>0.35</radius>
              <length>0.22</length>
            </cylinder>
          </geometry>
          <surface>
            <friction>
              <ode>
                <mu>1.0</mu>
                <mu2>0.8</mu2>
              </ode>
            </friction>
          </surface>
        </collision>
        <visual name="visual">
          <geometry>
            <cylinder>
              <radius>0.35</radius>
              <length>0.22</length>
            </cylinder>
          </geometry>
          <material>
            <ambient>0.1 0.1 0.1 1</ambient>
            <diffuse>0.15 0.15 0.15 1</diffuse>
          </material>
        </visual>
      </link>

      <!-- Rear Right Wheel -->
      <link name="rear_right_wheel">
        <pose>-1.4 -1.0 0 -1.5708 0 0</pose>
        <inertial>
          <mass>15.0</mass>
          <inertia>
            <ixx>0.3375</ixx>
            <iyy>0.3375</iyy>
            <izz>0.5625</izz>
            <ixy>0</ixy>
            <ixz>0</ixz>
            <iyz>0</iyz>
          </inertia>
        </inertial>
        <collision name="collision">
          <geometry>
            <cylinder>
              <radius>0.35</radius>
              <length>0.22</length>
            </cylinder>
          </geometry>
          <surface>
            <friction>
              <ode>
                <mu>1.0</mu>
                <mu2>0.8</mu2>
              </ode>
            </friction>
          </surface>
        </collision>
        <visual name="visual">
          <geometry>
            <cylinder>
              <radius>0.35</radius>
              <length>0.22</length>
            </cylinder>
          </geometry>
          <material>
            <ambient>0.1 0.1 0.1 1</ambient>
            <diffuse>0.15 0.15 0.15 1</diffuse>
          </material>
        </visual>
      </link>

      <!-- ============================================================ -->
      <!-- JOINTS                                                        -->
      <!-- ============================================================ -->

      <joint name="front_left_wheel_joint" type="revolute">
        <parent>chassis</parent>
        <child>front_left_wheel</child>
        <axis>
          <xyz>0 0 1</xyz>
          <limit>
            <lower>-1e16</lower>
            <upper>1e16</upper>
          </limit>
          <dynamics>
            <damping>0.5</damping>
            <friction>0.5</friction>
          </dynamics>
        </axis>
      </joint>

      <joint name="front_right_wheel_joint" type="revolute">
        <parent>chassis</parent>
        <child>front_right_wheel</child>
        <axis>
          <xyz>0 0 1</xyz>
          <limit>
            <lower>-1e16</lower>
            <upper>1e16</upper>
          </limit>
          <dynamics>
            <damping>0.5</damping>
            <friction>0.5</friction>
          </dynamics>
        </axis>
      </joint>

      <joint name="rear_left_wheel_joint" type="revolute">
        <parent>chassis</parent>
        <child>rear_left_wheel</child>
        <axis>
          <xyz>0 0 1</xyz>
          <limit>
            <lower>-1e16</lower>
            <upper>1e16</upper>
          </limit>
          <dynamics>
            <damping>0.5</damping>
            <friction>0.5</friction>
          </dynamics>
        </axis>
      </joint>

      <joint name="rear_right_wheel_joint" type="revolute">
        <parent>chassis</parent>
        <child>rear_right_wheel</child>
        <axis>
          <xyz>0 0 1</xyz>
          <limit>
            <lower>-1e16</lower>
            <upper>1e16</upper>
          </limit>
          <dynamics>
            <damping>0.5</damping>
            <friction>0.5</friction>
          </dynamics>
        </axis>
      </joint>

      <!-- ============================================================ -->
      <!-- DIFF DRIVE PLUGIN                                             -->
      <!-- ============================================================ -->
      <plugin
        filename="gz-sim-diff-drive-system"
        name="gz::sim::systems::DiffDrive">
        <left_joint>front_left_wheel_joint</left_joint>
        <left_joint>rear_left_wheel_joint</left_joint>
        <right_joint>front_right_wheel_joint</right_joint>
        <right_joint>rear_right_wheel_joint</right_joint>
        <wheel_separation>2.0</wheel_separation>
        <wheel_radius>0.35</wheel_radius>
        <max_linear_acceleration>3.0</max_linear_acceleration>
        <min_linear_acceleration>-5.0</min_linear_acceleration>
        <max_angular_acceleration>2.0</max_angular_acceleration>
        <min_angular_acceleration>-2.0</min_angular_acceleration>
        <odom_publish_frequency>50</odom_publish_frequency>
        <topic>chambers/cmd_vel</topic>
        <odom_topic>chambers/odom</odom_topic>
        <frame_id>odom</frame_id>
        <child_frame_id>base_link</child_frame_id>
      </plugin>

      <!-- Joint state publisher -->
      <plugin
        filename="gz-sim-joint-state-publisher-system"
        name="gz::sim::systems::JointStatePublisher">
        <topic>chambers/joint_states</topic>
      </plugin>

    </model>

    <!-- Spherical coordinates for NavSat (Munich, Germany) -->
    <spherical_coordinates>
      <surface_model>EARTH_WGS84</surface_model>
      <latitude_deg>48.1351</latitude_deg>
      <longitude_deg>11.5820</longitude_deg>
      <elevation>520</elevation>
      <heading_deg>0</heading_deg>
    </spherical_coordinates>

  </world>
</sdf>
